Workbook
Name Age30: Settings!$B$5
Name Age60: Settings!$B$6
Name Age90: Settings!$B$7
Name OpenAge: Settings!$B$13
Name OpenVal: Settings!$B$12
Name ShipDateUnits: Settings!$B$11
Name StartDate: Settings!$B$4
Name TotalShipped: Settings!$B$10

Sheet Instructions
A1: Component Inventory Tracker - How to Use
A2: Tracks how much money's worth of components is in storage and how long it sits before shipping.
A4: Set-up (do once)
B5: 1. Settings sheet | C5: Enter the go-live date (the day the opening inventory is counted). Change the 30/60/90-day aging limits if you like.
B6: 2. Items sheet | C6: Type each component's Item Code, Unit Cost and Opening Quantity in the yellow cells. Names are already filled in; edit them if needed. Room for 15 components (13 used).
A7: Day-to-day
B8: Received components | C8: Receiving sheet: use the next empty row. Enter the date, pick the item code from the drop-down, and enter the quantity. Name, cost and total cost fill in automatically.
B9: Shipped products | C9: Shipping sheet: use the next empty row. Enter the date, an order/serial number and how many finished products shipped. One of EVERY component is removed from stock automatically.
B10: Reading the results | C10: Dashboard sheet: total money in inventory, average days components sit before shipping, money by age bucket, and a per-component table with the aging flag.
A11: Colour key
B12: Yellow cell, blue text | C12: You type here.
B13: White / light-blue cell | C13: Calculated automatically. These cells are locked (sheet protection, no password) so formulas can't be overwritten by accident. Review > Unprotect Sheet if you need to change one.
B14: Fresh | C14: Oldest unshipped stock is within the first aging limit (default 30 days).
B15: Watch | C15: Past the first limit (default 31-60 days).
B16: Aging | C16: Past the second limit (default 61-90 days).
B17: Old | C17: Past the third limit (default over 90 days).
A18: Example of how entries look (not live data)
B19: Items | C19: Code: DS-100 Name: 64 GB SD Card Unit Cost: $12.50 Opening Qty: 40
B20: Receiving | C20: Date: 11/03/2026 Item Code: DS-100 Qty Received: 25 PO/Ref: PO-2231
B21: Shipping | C21: Date: 11/10/2026 Order/Serial #: SN-0007 Qty of Finished Products Shipped: 2
A22: Assumptions and how the numbers are calculated
B23: One of each component | C23: Every finished product contains exactly one of each component (stated by the company), so shipping N products uses N of every component.
B24: Opening stock date | C24: Arrival dates of existing stock are unknown, so it is dated on the go-live date in Settings. Its aging starts at zero on that date; aging for new deliveries is exact.
B25: First-in-first-out | C25: The oldest units are assumed to ship first. Days in storage for a shipped unit = ship date minus the date that unit was received.
B26: Average days before shipping | C26: Per component: average over all units shipped so far. Dashboard figure: cost-weighted average, so expensive components count more (matches the goal of dollars sitting in storage). Opening stock counts from the go-live date, not from its true arrival.
B27: Money in inventory | C27: On-hand quantity x the fixed unit cost entered on the Items sheet (costs do not change).
B28: Entry rules | C28: Keep Receiving and Shipping rows in date order and use the next empty row (don't leave gaps or sort the log). Room for 1,000 receipts and 1,000 shipments.
B29: Data check | C29: If a component shows negative stock, more products were logged as shipped than were received. Fix the log; averages are unreliable until then.
B30: Not included | C30: Returns, scrap/damage, and per-shipment average days are not tracked. For a count correction, add a receiving row for found stock; contact the builder to add other transaction types.

Sheet Dashboard
A1: Component Inventory Dashboard
A2: ="As of "&TEXT(TODAY(),"mm/dd/yyyy")&" | Dollar values are components at cost; aging = days since the oldest unshipped units were received." -> As of 10/15/2026 | Dollar values are components at cost; aging = days since the oldest unshipped units were received.
A3: Key Numbers
A4: Total value of components in inventory | B4: =SUM(Items!H5:H19) -> 142542
A5: Average days components stay in storage before shipping | B5: =IF(TotalShipped=0,"n/a",SUMPRODUCT(Items!C5:C19,Items!J5:J19)/SUM(Items!C5:C19)) -> n/a | D5: Cost-weighted average across all components (first-in-first-out).
A6: Finished products shipped (total) | B6: =TotalShipped -> 0
A7: Complete products that could be built from current stock | B7: =IF(COUNT(Items!G5:G19)=0,"n/a",MAX(0,MIN(Items!G5:G19))) -> 0
A8: Components flagged Aging or Old | B8: =COUNTIF(Items!L5:L19,"Aging")+COUNTIF(Items!L5:L19,"Old") -> 11
A9: Data check | B9: =IF(COUNTIF(Items!G5:G19,"<0")>0,"CHECK: negative stock on a component","OK") -> OK
A11: Money in Storage by Age
A12: Age bucket | B12: From (days) | C12: To (days) | D12: Value ($) | E12: % of total
A13: ="0-"&AGE30&" days (Fresh)" -> 0- days (Fresh) | B13: 0 | C13: =AGE30 -> 0 | D13: =SUMIFS(Receiving!$K$5:$K$1004,Receiving!$L$5:$L$1004,">="&B13,Receiving!$L$5:$L$1004,"<="&C13)+IF(AND(OpenAge>=B13,OpenAge<=C13),OpenVal,0) -> 0 | E13: =IF($D$17=0,0,D13/$D$17) -> 0
A14: =(AGE30+1)&"-"&AGE60&" days (Watch)" -> 1- days (Watch) | B14: =AGE30+1 -> 1 | C14: =AGE60 -> 0 | D14: =SUMIFS(Receiving!$K$5:$K$1004,Receiving!$L$5:$L$1004,">="&B14,Receiving!$L$5:$L$1004,"<="&C14)+IF(AND(OpenAge>=B14,OpenAge<=C14),OpenVal,0) -> 0 | E14: =IF($D$17=0,0,D14/$D$17) -> 0
A15: =(AGE60+1)&"-"&AGE90&" days (Aging)" -> 1- days (Aging) | B15: =AGE60+1 -> 1 | C15: =AGE90 -> 0 | D15: =SUMIFS(Receiving!$K$5:$K$1004,Receiving!$L$5:$L$1004,">="&B15,Receiving!$L$5:$L$1004,"<="&C15)+IF(AND(OpenAge>=B15,OpenAge<=C15),OpenVal,0) -> 0 | E15: =IF($D$17=0,0,D15/$D$17) -> 0
A16: ="Over "&AGE90&" days (Old)" -> Over days (Old) | B16: =AGE90+1 -> 1 | C16: =99999 -> 99999 | D16: =SUMIFS(Receiving!$K$5:$K$1004,Receiving!$L$5:$L$1004,">="&B16,Receiving!$L$5:$L$1004,"<="&C16)+IF(AND(OpenAge>=B16,OpenAge<=C16),OpenVal,0) -> 142542 | E16: =IF($D$17=0,0,D16/$D$17) -> 1
A17: Total | D17: =SUM(D13:D16) -> 142542 | E17: =SUM(E13:E16) -> 1 | F17: =IF(ROUND(D17-B4,2)=0,"Ties to total value","Does not tie - check data") -> Ties to total value
A19: By Component
A20: Component | B20: Item Code | C20: Unit Cost ($) | D20: On Hand | E20: Value ($) | F20: Avg Days in Storage Before Shipping | G20: Age of Oldest Stock On Hand (days) | H20: Aging Flag
A21: =IF(Items!B5="","",Items!B5) -> Vanilla Ice Cream Mix | B21: =IF(Items!A5="","",Items!A5) -> TNA-019 | C21: =IF(Items!A5="","",Items!C5) -> 80 | D21: =IF(Items!A5="","",Items!G5) -> 78 | E21: =IF(Items!A5="","",Items!H5) -> 6240 | F21: =IF(Items!A5="","",Items!J5) | G21: =IF(Items!A5="","",Items!K5) -> 1 | H21: =IF(Items!A5="","",Items!L5) -> Old
A22: =IF(Items!B6="","",Items!B6) -> Chocolate Ice Cream Mix | B22: =IF(Items!A6="","",Items!A6) -> TNA-481 | C22: =IF(Items!A6="","",Items!C6) -> 80 | D22: =IF(Items!A6="","",Items!G6) -> 9 | E22: =IF(Items!A6="","",Items!H6) -> 720 | F22: =IF(Items!A6="","",Items!J6) | G22: =IF(Items!A6="","",Items!K6) -> 1 | H22: =IF(Items!A6="","",Items!L6) -> Old
A23: =IF(Items!B7="","",Items!B7) -> Strawberry Ice Cream Mix | B23: =IF(Items!A7="","",Items!A7) -> TNA-083 | C23: =IF(Items!A7="","",Items!C7) -> 80 | D23: =IF(Items!A7="","",Items!G7) -> 0 | E23: =IF(Items!A7="","",Items!H7) -> 0 | F23: =IF(Items!A7="","",Items!J7) | G23: =IF(Items!A7="","",Items!K7) | H23: =IF(Items!A7="","",Items!L7) -> Empty
A24: =IF(Items!B8="","",Items!B8) -> Rainbow Spinkles | B24: =IF(Items!A8="","",Items!A8) -> TNA-032 | C24: =IF(Items!A8="","",Items!C8) -> 700 | D24: =IF(Items!A8="","",Items!G8) -> 130 | E24: =IF(Items!A8="","",Items!H8) -> 91000 | F24: =IF(Items!A8="","",Items!J8) | G24: =IF(Items!A8="","",Items!K8) -> 1 | H24: =IF(Items!A8="","",Items!L8) -> Old
A25: =IF(Items!B9="","",Items!B9) -> Chocolate Syrup | B25: =IF(Items!A9="","",Items!A9) -> TNA-321 | C25: =IF(Items!A9="","",Items!C9) -> 56 | D25: =IF(Items!A9="","",Items!G9) -> 12 | E25: =IF(Items!A9="","",Items!H9) -> 672 | F25: =IF(Items!A9="","",Items!J9) | G25: =IF(Items!A9="","",Items!K9) -> 1 | H25: =IF(Items!A9="","",Items!L9) -> Old
A26: =IF(Items!B10="","",Items!B10) -> Caramel Sauce | B26: =IF(Items!A10="","",Items!A10) -> TNA-257 | C26: =IF(Items!A10="","",Items!C10) -> 90 | D26: =IF(Items!A10="","",Items!G10) -> 6 | E26: =IF(Items!A10="","",Items!H10) -> 540 | F26: =IF(Items!A10="","",Items!J10) | G26: =IF(Items!A10="","",Items!K10) -> 1 | H26: =IF(Items!A10="","",Items!L10) -> Old
A27: =IF(Items!B11="","",Items!B11) -> Cruched Oreo Cookies | B27: =IF(Items!A11="","",Items!A11) -> TNA-05 | C27: =IF(Items!A11="","",Items!C11) -> 150 | D27: =IF(Items!A11="","",Items!G11) -> 253 | E27: =IF(Items!A11="","",Items!H11) -> 37950 | F27: =IF(Items!A11="","",Items!J11) | G27: =IF(Items!A11="","",Items!K11) -> 1 | H27: =IF(Items!A11="","",Items!L11) -> Old
A28: =IF(Items!B12="","",Items!B12) -> Choppped Peanuts | B28: =IF(Items!A12="","",Items!A12) -> TNA-017 | C28: =IF(Items!A12="","",Items!C12) -> 75 | D28: =IF(Items!A12="","",Items!G12) -> 40 | E28: =IF(Items!A12="","",Items!H12) -> 3000 | F28: =IF(Items!A12="","",Items!J12) | G28: =IF(Items!A12="","",Items!K12) -> 1 | H28: =IF(Items!A12="","",Items!L12) -> Old
A29: =IF(Items!B13="","",Items!B13) -> Waffle Cones | B29: =IF(Items!A13="","",Items!A13) -> TNA-045 | C29: =IF(Items!A13="","",Items!C13) -> 30 | D29: =IF(Items!A13="","",Items!G13) -> 3 | E29: =IF(Items!A13="","",Items!H13) -> 90 | F29: =IF(Items!A13="","",Items!J13) | G29: =IF(Items!A13="","",Items!K13) -> 1 | H29: =IF(Items!A13="","",Items!L13) -> Old
A30: =IF(Items!B14="","",Items!B14) -> Sugar Cones | B30: =IF(Items!A14="","",Items!A14) -> TNA-900 | C30: =IF(Items!A14="","",Items!C14) -> 45 | D30: =IF(Items!A14="","",Items!G14) -> 0 | E30: =IF(Items!A14="","",Items!H14) -> 0 | F30: =IF(Items!A14="","",Items!J14) | G30: =IF(Items!A14="","",Items!K14) | H30: =IF(Items!A14="","",Items!L14) -> Empty
A31: =IF(Items!B15="","",Items!B15) -> Ice Cream Cups | B31: =IF(Items!A15="","",Items!A15) -> TNA-067 | C31: =IF(Items!A15="","",Items!C15) -> 55 | D31: =IF(Items!A15="","",Items!G15) -> 22 | E31: =IF(Items!A15="","",Items!H15) -> 1210 | F31: =IF(Items!A15="","",Items!J15) | G31: =IF(Items!A15="","",Items!K15) -> 1 | H31: =IF(Items!A15="","",Items!L15) -> Old
A32: =IF(Items!B16="","",Items!B16) -> Plastic Ice Cream Spoons | B32: =IF(Items!A16="","",Items!A16) -> TNA-787 | C32: =IF(Items!A16="","",Items!C16) -> 30 | D32: =IF(Items!A16="","",Items!G16) -> 4 | E32: =IF(Items!A16="","",Items!H16) -> 120 | F32: =IF(Items!A16="","",Items!J16) | G32: =IF(Items!A16="","",Items!K16) -> 1 | H32: =IF(Items!A16="","",Items!L16) -> Old
... A35: =IF(Items!B19="","",Items!B19) | B35: =IF(Items!A19="","",Items!A19) | C35: =IF(Items!A19="","",Items!C19) | D35: =IF(Items!A19="","",Items!G19) | E35: =IF(Items!A19="","",Items!H19) | F35: =IF(Items!A19="","",Items!J19) | G35: =IF(Items!A19="","",Items!K19) | H35: =IF(Items!A19="","",Items!L19)
A36: Total | E36: =SUM(E21:E35) -> 142542

Sheet Items
A1: Items - Component Master List & Current Stock
A2: Enter Item Code, Unit Cost and Opening Quantity in the yellow cells (names are pre-filled from your list and can be edited). Columns E onward calculate automatically.
A4: Item Code | B4: Item Name | C4: Unit Cost ($) | D4: Opening Qty (at go-live) | E4: Qty Received (from Receiving log) | F4: Qty Used (finished products shipped) | G4: On Hand | H4: Inventory Value ($) | I4: Opening Qty Still on Hand | J4: Avg Days in Storage Before Shipping | K4: Age of Oldest Stock On Hand (days) | L4: Aging Flag
A5: TNA-019 | B5: Vanilla Ice Cream Mix | C5: 80 | D5: 78 | E5: =IF($A5="","",SUMIFS(Receiving!$D$5:$D$1004,Receiving!$B$5:$B$1004,$A5)) -> 0 | F5: =IF($A5="","",TotalShipped) -> 0 | G5: =IF($A5="","",D5+E5-F5) -> 78 | H5: =IF($A5="","",MAX(0,G5)*C5) -> 6240 | I5: =IF($A5="","",MAX(0,D5-TotalShipped)) -> 78 | J5: =IF(OR($A5="",TotalShipped=0),"",(ShipDateUnits-(MIN(D5,TotalShipped)*StartDate+SUMIFS(Receiving!$N$5:$N$1004,Receiving!$B$5:$B$1004,$A5)))/TotalShipped) | K5: =IF(OR($A5="",G5<=0),"",TODAY()-IF(I5>0,StartDate,_xlfn.MINIFS(Receiving!$A$5:$A$1004,Receiving!$B$5:$B$1004,$A5,Receiving!$I$5:$I$1004,">0"))) -> 1 | L5: =IF($A5="","",IF(G5<0,"CHECK COUNT",IF(G5=0,"Empty",IF(K5<=AGE30,"Fresh",IF(K5<=AGE60,"Watch",IF(K5<=AGE90,"Aging","Old")))))) -> Old
A6: TNA-481 | B6: Chocolate Ice Cream Mix | C6: 80 | D6: 9 | E6: =IF($A6="","",SUMIFS(Receiving!$D$5:$D$1004,Receiving!$B$5:$B$1004,$A6)) -> 0 | F6: =IF($A6="","",TotalShipped) -> 0 | G6: =IF($A6="","",D6+E6-F6) -> 9 | H6: =IF($A6="","",MAX(0,G6)*C6) -> 720 | I6: =IF($A6="","",MAX(0,D6-TotalShipped)) -> 9 | J6: =IF(OR($A6="",TotalShipped=0),"",(ShipDateUnits-(MIN(D6,TotalShipped)*StartDate+SUMIFS(Receiving!$N$5:$N$1004,Receiving!$B$5:$B$1004,$A6)))/TotalShipped) | K6: =IF(OR($A6="",G6<=0),"",TODAY()-IF(I6>0,StartDate,_xlfn.MINIFS(Receiving!$A$5:$A$1004,Receiving!$B$5:$B$1004,$A6,Receiving!$I$5:$I$1004,">0"))) -> 1 | L6: =IF($A6="","",IF(G6<0,"CHECK COUNT",IF(G6=0,"Empty",IF(K6<=AGE30,"Fresh",IF(K6<=AGE60,"Watch",IF(K6<=AGE90,"Aging","Old")))))) -> Old
A7: TNA-083 | B7: Strawberry Ice Cream Mix | C7: 80 | D7: 0 | E7: =IF($A7="","",SUMIFS(Receiving!$D$5:$D$1004,Receiving!$B$5:$B$1004,$A7)) -> 0 | F7: =IF($A7="","",TotalShipped) -> 0 | G7: =IF($A7="","",D7+E7-F7) -> 0 | H7: =IF($A7="","",MAX(0,G7)*C7) -> 0 | I7: =IF($A7="","",MAX(0,D7-TotalShipped)) -> 0 | J7: =IF(OR($A7="",TotalShipped=0),"",(ShipDateUnits-(MIN(D7,TotalShipped)*StartDate+SUMIFS(Receiving!$N$5:$N$1004,Receiving!$B$5:$B$1004,$A7)))/TotalShipped) | K7: =IF(OR($A7="",G7<=0),"",TODAY()-IF(I7>0,StartDate,_xlfn.MINIFS(Receiving!$A$5:$A$1004,Receiving!$B$5:$B$1004,$A7,Receiving!$I$5:$I$1004,">0"))) | L7: =IF($A7="","",IF(G7<0,"CHECK COUNT",IF(G7=0,"Empty",IF(K7<=AGE30,"Fresh",IF(K7<=AGE60,"Watch",IF(K7<=AGE90,"Aging","Old")))))) -> Empty
A8: TNA-032 | B8: Rainbow Spinkles | C8: 700 | D8: 130 | E8: =IF($A8="","",SUMIFS(Receiving!$D$5:$D$1004,Receiving!$B$5:$B$1004,$A8)) -> 0 | F8: =IF($A8="","",TotalShipped) -> 0 | G8: =IF($A8="","",D8+E8-F8) -> 130 | H8: =IF($A8="","",MAX(0,G8)*C8) -> 91000 | I8: =IF($A8="","",MAX(0,D8-TotalShipped)) -> 130 | J8: =IF(OR($A8="",TotalShipped=0),"",(ShipDateUnits-(MIN(D8,TotalShipped)*StartDate+SUMIFS(Receiving!$N$5:$N$1004,Receiving!$B$5:$B$1004,$A8)))/TotalShipped) | K8: =IF(OR($A8="",G8<=0),"",TODAY()-IF(I8>0,StartDate,_xlfn.MINIFS(Receiving!$A$5:$A$1004,Receiving!$B$5:$B$1004,$A8,Receiving!$I$5:$I$1004,">0"))) -> 1 | L8: =IF($A8="","",IF(G8<0,"CHECK COUNT",IF(G8=0,"Empty",IF(K8<=AGE30,"Fresh",IF(K8<=AGE60,"Watch",IF(K8<=AGE90,"Aging","Old")))))) -> Old
A9: TNA-321 | B9: Chocolate Syrup | C9: 56 | D9: 12 | E9: =IF($A9="","",SUMIFS(Receiving!$D$5:$D$1004,Receiving!$B$5:$B$1004,$A9)) -> 0 | F9: =IF($A9="","",TotalShipped) -> 0 | G9: =IF($A9="","",D9+E9-F9) -> 12 | H9: =IF($A9="","",MAX(0,G9)*C9) -> 672 | I9: =IF($A9="","",MAX(0,D9-TotalShipped)) -> 12 | J9: =IF(OR($A9="",TotalShipped=0),"",(ShipDateUnits-(MIN(D9,TotalShipped)*StartDate+SUMIFS(Receiving!$N$5:$N$1004,Receiving!$B$5:$B$1004,$A9)))/TotalShipped) | K9: =IF(OR($A9="",G9<=0),"",TODAY()-IF(I9>0,StartDate,_xlfn.MINIFS(Receiving!$A$5:$A$1004,Receiving!$B$5:$B$1004,$A9,Receiving!$I$5:$I$1004,">0"))) -> 1 | L9: =IF($A9="","",IF(G9<0,"CHECK COUNT",IF(G9=0,"Empty",IF(K9<=AGE30,"Fresh",IF(K9<=AGE60,"Watch",IF(K9<=AGE90,"Aging","Old")))))) -> Old
A10: TNA-257 | B10: Caramel Sauce | C10: 90 | D10: 6 | E10: =IF($A10="","",SUMIFS(Receiving!$D$5:$D$1004,Receiving!$B$5:$B$1004,$A10)) -> 0 | F10: =IF($A10="","",TotalShipped) -> 0 | G10: =IF($A10="","",D10+E10-F10) -> 6 | H10: =IF($A10="","",MAX(0,G10)*C10) -> 540 | I10: =IF($A10="","",MAX(0,D10-TotalShipped)) -> 6 | J10: =IF(OR($A10="",TotalShipped=0),"",(ShipDateUnits-(MIN(D10,TotalShipped)*StartDate+SUMIFS(Receiving!$N$5:$N$1004,Receiving!$B$5:$B$1004,$A10)))/TotalShipped) | K10: =IF(OR($A10="",G10<=0),"",TODAY()-IF(I10>0,StartDate,_xlfn.MINIFS(Receiving!$A$5:$A$1004,Receiving!$B$5:$B$1004,$A10,Receiving!$I$5:$I$1004,">0"))) -> 1 | L10: =IF($A10="","",IF(G10<0,"CHECK COUNT",IF(G10=0,"Empty",IF(K10<=AGE30,"Fresh",IF(K10<=AGE60,"Watch",IF(K10<=AGE90,"Aging","Old")))))) -> Old
A11: TNA-05 | B11: Cruched Oreo Cookies | C11: 150 | D11: 253 | E11: =IF($A11="","",SUMIFS(Receiving!$D$5:$D$1004,Receiving!$B$5:$B$1004,$A11)) -> 0 | F11: =IF($A11="","",TotalShipped) -> 0 | G11: =IF($A11="","",D11+E11-F11) -> 253 | H11: =IF($A11="","",MAX(0,G11)*C11) -> 37950 | I11: =IF($A11="","",MAX(0,D11-TotalShipped)) -> 253 | J11: =IF(OR($A11="",TotalShipped=0),"",(ShipDateUnits-(MIN(D11,TotalShipped)*StartDate+SUMIFS(Receiving!$N$5:$N$1004,Receiving!$B$5:$B$1004,$A11)))/TotalShipped) | K11: =IF(OR($A11="",G11<=0),"",TODAY()-IF(I11>0,StartDate,_xlfn.MINIFS(Receiving!$A$5:$A$1004,Receiving!$B$5:$B$1004,$A11,Receiving!$I$5:$I$1004,">0"))) -> 1 | L11: =IF($A11="","",IF(G11<0,"CHECK COUNT",IF(G11=0,"Empty",IF(K11<=AGE30,"Fresh",IF(K11<=AGE60,"Watch",IF(K11<=AGE90,"Aging","Old")))))) -> Old
A12: TNA-017 | B12: Choppped Peanuts | C12: 75 | D12: 40 | E12: =IF($A12="","",SUMIFS(Receiving!$D$5:$D$1004,Receiving!$B$5:$B$1004,$A12)) -> 0 | F12: =IF($A12="","",TotalShipped) -> 0 | G12: =IF($A12="","",D12+E12-F12) -> 40 | H12: =IF($A12="","",MAX(0,G12)*C12) -> 3000 | I12: =IF($A12="","",MAX(0,D12-TotalShipped)) -> 40 | J12: =IF(OR($A12="",TotalShipped=0),"",(ShipDateUnits-(MIN(D12,TotalShipped)*StartDate+SUMIFS(Receiving!$N$5:$N$1004,Receiving!$B$5:$B$1004,$A12)))/TotalShipped) | K12: =IF(OR($A12="",G12<=0),"",TODAY()-IF(I12>0,StartDate,_xlfn.MINIFS(Receiving!$A$5:$A$1004,Receiving!$B$5:$B$1004,$A12,Receiving!$I$5:$I$1004,">0"))) -> 1 | L12: =IF($A12="","",IF(G12<0,"CHECK COUNT",IF(G12=0,"Empty",IF(K12<=AGE30,"Fresh",IF(K12<=AGE60,"Watch",IF(K12<=AGE90,"Aging","Old")))))) -> Old
A13: TNA-045 | B13: Waffle Cones | C13: 30 | D13: 3 | E13: =IF($A13="","",SUMIFS(Receiving!$D$5:$D$1004,Receiving!$B$5:$B$1004,$A13)) -> 0 | F13: =IF($A13="","",TotalShipped) -> 0 | G13: =IF($A13="","",D13+E13-F13) -> 3 | H13: =IF($A13="","",MAX(0,G13)*C13) -> 90 | I13: =IF($A13="","",MAX(0,D13-TotalShipped)) -> 3 | J13: =IF(OR($A13="",TotalShipped=0),"",(ShipDateUnits-(MIN(D13,TotalShipped)*StartDate+SUMIFS(Receiving!$N$5:$N$1004,Receiving!$B$5:$B$1004,$A13)))/TotalShipped) | K13: =IF(OR($A13="",G13<=0),"",TODAY()-IF(I13>0,StartDate,_xlfn.MINIFS(Receiving!$A$5:$A$1004,Receiving!$B$5:$B$1004,$A13,Receiving!$I$5:$I$1004,">0"))) -> 1 | L13: =IF($A13="","",IF(G13<0,"CHECK COUNT",IF(G13=0,"Empty",IF(K13<=AGE30,"Fresh",IF(K13<=AGE60,"Watch",IF(K13<=AGE90,"Aging","Old")))))) -> Old
A14: TNA-900 | B14: Sugar Cones | C14: 45 | D14: 0 | E14: =IF($A14="","",SUMIFS(Receiving!$D$5:$D$1004,Receiving!$B$5:$B$1004,$A14)) -> 0 | F14: =IF($A14="","",TotalShipped) -> 0 | G14: =IF($A14="","",D14+E14-F14) -> 0 | H14: =IF($A14="","",MAX(0,G14)*C14) -> 0 | I14: =IF($A14="","",MAX(0,D14-TotalShipped)) -> 0 | J14: =IF(OR($A14="",TotalShipped=0),"",(ShipDateUnits-(MIN(D14,TotalShipped)*StartDate+SUMIFS(Receiving!$N$5:$N$1004,Receiving!$B$5:$B$1004,$A14)))/TotalShipped) | K14: =IF(OR($A14="",G14<=0),"",TODAY()-IF(I14>0,StartDate,_xlfn.MINIFS(Receiving!$A$5:$A$1004,Receiving!$B$5:$B$1004,$A14,Receiving!$I$5:$I$1004,">0"))) | L14: =IF($A14="","",IF(G14<0,"CHECK COUNT",IF(G14=0,"Empty",IF(K14<=AGE30,"Fresh",IF(K14<=AGE60,"Watch",IF(K14<=AGE90,"Aging","Old")))))) -> Empty
A15: TNA-067 | B15: Ice Cream Cups | C15: 55 | D15: 22 | E15: =IF($A15="","",SUMIFS(Receiving!$D$5:$D$1004,Receiving!$B$5:$B$1004,$A15)) -> 0 | F15: =IF($A15="","",TotalShipped) -> 0 | G15: =IF($A15="","",D15+E15-F15) -> 22 | H15: =IF($A15="","",MAX(0,G15)*C15) -> 1210 | I15: =IF($A15="","",MAX(0,D15-TotalShipped)) -> 22 | J15: =IF(OR($A15="",TotalShipped=0),"",(ShipDateUnits-(MIN(D15,TotalShipped)*StartDate+SUMIFS(Receiving!$N$5:$N$1004,Receiving!$B$5:$B$1004,$A15)))/TotalShipped) | K15: =IF(OR($A15="",G15<=0),"",TODAY()-IF(I15>0,StartDate,_xlfn.MINIFS(Receiving!$A$5:$A$1004,Receiving!$B$5:$B$1004,$A15,Receiving!$I$5:$I$1004,">0"))) -> 1 | L15: =IF($A15="","",IF(G15<0,"CHECK COUNT",IF(G15=0,"Empty",IF(K15<=AGE30,"Fresh",IF(K15<=AGE60,"Watch",IF(K15<=AGE90,"Aging","Old")))))) -> Old
A16: TNA-787 | B16: Plastic Ice Cream Spoons | C16: 30 | D16: 4 | E16: =IF($A16="","",SUMIFS(Receiving!$D$5:$D$1004,Receiving!$B$5:$B$1004,$A16)) -> 0 | F16: =IF($A16="","",TotalShipped) -> 0 | G16: =IF($A16="","",D16+E16-F16) -> 4 | H16: =IF($A16="","",MAX(0,G16)*C16) -> 120 | I16: =IF($A16="","",MAX(0,D16-TotalShipped)) -> 4 | J16: =IF(OR($A16="",TotalShipped=0),"",(ShipDateUnits-(MIN(D16,TotalShipped)*StartDate+SUMIFS(Receiving!$N$5:$N$1004,Receiving!$B$5:$B$1004,$A16)))/TotalShipped) | K16: =IF(OR($A16="",G16<=0),"",TODAY()-IF(I16>0,StartDate,_xlfn.MINIFS(Receiving!$A$5:$A$1004,Receiving!$B$5:$B$1004,$A16,Receiving!$I$5:$I$1004,">0"))) -> 1 | L16: =IF($A16="","",IF(G16<0,"CHECK COUNT",IF(G16=0,"Empty",IF(K16<=AGE30,"Fresh",IF(K16<=AGE60,"Watch",IF(K16<=AGE90,"Aging","Old")))))) -> Old
A17: TNA-086 | B17: Disposable Gloves | C17: 20 | D17: 50 | E17: =IF($A17="","",SUMIFS(Receiving!$D$5:$D$1004,Receiving!$B$5:$B$1004,$A17)) -> 0 | F17: =IF($A17="","",TotalShipped) -> 0 | G17: =IF($A17="","",D17+E17-F17) -> 50 | H17: =IF($A17="","",MAX(0,G17)*C17) -> 1000 | I17: =IF($A17="","",MAX(0,D17-TotalShipped)) -> 50 | J17: =IF(OR($A17="",TotalShipped=0),"",(ShipDateUnits-(MIN(D17,TotalShipped)*StartDate+SUMIFS(Receiving!$N$5:$N$1004,Receiving!$B$5:$B$1004,$A17)))/TotalShipped) | K17: =IF(OR($A17="",G17<=0),"",TODAY()-IF(I17>0,StartDate,_xlfn.MINIFS(Receiving!$A$5:$A$1004,Receiving!$B$5:$B$1004,$A17,Receiving!$I$5:$I$1004,">0"))) -> 1 | L17: =IF($A17="","",IF(G17<0,"CHECK COUNT",IF(G17=0,"Empty",IF(K17<=AGE30,"Fresh",IF(K17<=AGE60,"Watch",IF(K17<=AGE90,"Aging","Old")))))) -> Old
E18: =IF($A18="","",SUMIFS(Receiving!$D$5:$D$1004,Receiving!$B$5:$B$1004,$A18)) | F18: =IF($A18="","",TotalShipped) | G18: =IF($A18="","",D18+E18-F18) | H18: =IF($A18="","",MAX(0,G18)*C18) | I18: =IF($A18="","",MAX(0,D18-TotalShipped)) | J18: =IF(OR($A18="",TotalShipped=0),"",(ShipDateUnits-(MIN(D18,TotalShipped)*StartDate+SUMIFS(Receiving!$N$5:$N$1004,Receiving!$B$5:$B$1004,$A18)))/TotalShipped) | K18: =IF(OR($A18="",G18<=0),"",TODAY()-IF(I18>0,StartDate,_xlfn.MINIFS(Receiving!$A$5:$A$1004,Receiving!$B$5:$B$1004,$A18,Receiving!$I$5:$I$1004,">0"))) | L18: =IF($A18="","",IF(G18<0,"CHECK COUNT",IF(G18=0,"Empty",IF(K18<=AGE30,"Fresh",IF(K18<=AGE60,"Watch",IF(K18<=AGE90,"Aging","Old"))))))
E19: =IF($A19="","",SUMIFS(Receiving!$D$5:$D$1004,Receiving!$B$5:$B$1004,$A19)) | F19: =IF($A19="","",TotalShipped) | G19: =IF($A19="","",D19+E19-F19) | H19: =IF($A19="","",MAX(0,G19)*C19) | I19: =IF($A19="","",MAX(0,D19-TotalShipped)) | J19: =IF(OR($A19="",TotalShipped=0),"",(ShipDateUnits-(MIN(D19,TotalShipped)*StartDate+SUMIFS(Receiving!$N$5:$N$1004,Receiving!$B$5:$B$1004,$A19)))/TotalShipped) | K19: =IF(OR($A19="",G19<=0),"",TODAY()-IF(I19>0,StartDate,_xlfn.MINIFS(Receiving!$A$5:$A$1004,Receiving!$B$5:$B$1004,$A19,Receiving!$I$5:$I$1004,">0"))) | L19: =IF($A19="","",IF(G19<0,"CHECK COUNT",IF(G19=0,"Empty",IF(K19<=AGE30,"Fresh",IF(K19<=AGE60,"Watch",IF(K19<=AGE90,"Aging","Old"))))))
A20: TOTAL | H20: =SUM(H5:H19) -> 142542
A22: Notes: 'Qty Used' equals total finished products shipped because every product contains one of each component. 'Avg Days in Storage Before Shipping' uses first-in-first-out (oldest stock ships first). Opening stock is dated on the go-live date in Settings.

Sheet Receiving
A1: Receiving Log - Components Coming Into Storage
A2: Add one row per delivery in the next empty row (keep rows in date order). Fill the yellow columns only; grey-blue columns calculate automatically.
A4: Date Received | B4: Item Code (pick from list) | C4: Item Name | D4: Qty Received | E4: Unit Cost ($) | F4: Total Cost ($) | G4: PO / Ref # (optional) | H4: Units Before (this item, earlier) | I4: Units Still in Storage | J4: Units Already Shipped | K4: Value Still in Storage ($) | L4: Age of Remaining Units (days) | M4: Aging Status | N4: Date x Units Shipped (helper)
A5: 46296 | B5: FNN-145 | C5: =IF(B5="","",IFERROR(INDEX(Items!$B$5:$B$19,MATCH(B5,Items!$A$5:$A$19,0)),"Unknown code")) -> Unknown code | D5: 5 | E5: =IF(B5="","",IFERROR(INDEX(Items!$C$5:$C$19,MATCH(B5,Items!$A$5:$A$19,0)),"")) | F5: =IF(OR(D5="",E5=""),"",D5*E5) | H5: =IF(OR(A5="",B5="",D5=""),"",IFERROR(INDEX(Items!$D$5:$D$19,MATCH(B5,Items!$A$5:$A$19,0))+SUMIFS(D$4:D4,B$4:B4,B5),"")) | I5: =IF(H5="","",MAX(0,MIN(D5,H5+D5-TotalShipped))) | J5: =IF(H5="","",D5-I5) | K5: =IF(OR(H5="",E5=""),"",I5*E5) | L5: =IF(H5="","",IF(I5>0,TODAY()-A5,"")) | M5: =IF(H5="","",IF(I5<=0,"Shipped",IF(L5<=AGE30,"Fresh",IF(L5<=AGE60,"Watch",IF(L5<=AGE90,"Aging","Old"))))) | N5: =IF(H5="","",J5*A5)
C6: =IF(B6="","",IFERROR(INDEX(Items!$B$5:$B$19,MATCH(B6,Items!$A$5:$A$19,0)),"Unknown code")) | E6: =IF(B6="","",IFERROR(INDEX(Items!$C$5:$C$19,MATCH(B6,Items!$A$5:$A$19,0)),"")) | F6: =IF(OR(D6="",E6=""),"",D6*E6) | H6: =IF(OR(A6="",B6="",D6=""),"",IFERROR(INDEX(Items!$D$5:$D$19,MATCH(B6,Items!$A$5:$A$19,0))+SUMIFS(D$4:D5,B$4:B5,B6),"")) | I6: =IF(H6="","",MAX(0,MIN(D6,H6+D6-TotalShipped))) | J6: =IF(H6="","",D6-I6) | K6: =IF(OR(H6="",E6=""),"",I6*E6) | L6: =IF(H6="","",IF(I6>0,TODAY()-A6,"")) | M6: =IF(H6="","",IF(I6<=0,"Shipped",IF(L6<=AGE30,"Fresh",IF(L6<=AGE60,"Watch",IF(L6<=AGE90,"Aging","Old"))))) | N6: =IF(H6="","",J6*A6)
C7: =IF(B7="","",IFERROR(INDEX(Items!$B$5:$B$19,MATCH(B7,Items!$A$5:$A$19,0)),"Unknown code")) | E7: =IF(B7="","",IFERROR(INDEX(Items!$C$5:$C$19,MATCH(B7,Items!$A$5:$A$19,0)),"")) | F7: =IF(OR(D7="",E7=""),"",D7*E7) | H7: =IF(OR(A7="",B7="",D7=""),"",IFERROR(INDEX(Items!$D$5:$D$19,MATCH(B7,Items!$A$5:$A$19,0))+SUMIFS(D$4:D6,B$4:B6,B7),"")) | I7: =IF(H7="","",MAX(0,MIN(D7,H7+D7-TotalShipped))) | J7: =IF(H7="","",D7-I7) | K7: =IF(OR(H7="",E7=""),"",I7*E7) | L7: =IF(H7="","",IF(I7>0,TODAY()-A7,"")) | M7: =IF(H7="","",IF(I7<=0,"Shipped",IF(L7<=AGE30,"Fresh",IF(L7<=AGE60,"Watch",IF(L7<=AGE90,"Aging","Old"))))) | N7: =IF(H7="","",J7*A7)
C8: =IF(B8="","",IFERROR(INDEX(Items!$B$5:$B$19,MATCH(B8,Items!$A$5:$A$19,0)),"Unknown code")) | E8: =IF(B8="","",IFERROR(INDEX(Items!$C$5:$C$19,MATCH(B8,Items!$A$5:$A$19,0)),"")) | F8: =IF(OR(D8="",E8=""),"",D8*E8) | H8: =IF(OR(A8="",B8="",D8=""),"",IFERROR(INDEX(Items!$D$5:$D$19,MATCH(B8,Items!$A$5:$A$19,0))+SUMIFS(D$4:D7,B$4:B7,B8),"")) | I8: =IF(H8="","",MAX(0,MIN(D8,H8+D8-TotalShipped))) | J8: =IF(H8="","",D8-I8) | K8: =IF(OR(H8="",E8=""),"",I8*E8) | L8: =IF(H8="","",IF(I8>0,TODAY()-A8,"")) | M8: =IF(H8="","",IF(I8<=0,"Shipped",IF(L8<=AGE30,"Fresh",IF(L8<=AGE60,"Watch",IF(L8<=AGE90,"Aging","Old"))))) | N8: =IF(H8="","",J8*A8)
C9: =IF(B9="","",IFERROR(INDEX(Items!$B$5:$B$19,MATCH(B9,Items!$A$5:$A$19,0)),"Unknown code")) | E9: =IF(B9="","",IFERROR(INDEX(Items!$C$5:$C$19,MATCH(B9,Items!$A$5:$A$19,0)),"")) | F9: =IF(OR(D9="",E9=""),"",D9*E9) | H9: =IF(OR(A9="",B9="",D9=""),"",IFERROR(INDEX(Items!$D$5:$D$19,MATCH(B9,Items!$A$5:$A$19,0))+SUMIFS(D$4:D8,B$4:B8,B9),"")) | I9: =IF(H9="","",MAX(0,MIN(D9,H9+D9-TotalShipped))) | J9: =IF(H9="","",D9-I9) | K9: =IF(OR(H9="",E9=""),"",I9*E9) | L9: =IF(H9="","",IF(I9>0,TODAY()-A9,"")) | M9: =IF(H9="","",IF(I9<=0,"Shipped",IF(L9<=AGE30,"Fresh",IF(L9<=AGE60,"Watch",IF(L9<=AGE90,"Aging","Old"))))) | N9: =IF(H9="","",J9*A9)
C10: =IF(B10="","",IFERROR(INDEX(Items!$B$5:$B$19,MATCH(B10,Items!$A$5:$A$19,0)),"Unknown code")) | E10: =IF(B10="","",IFERROR(INDEX(Items!$C$5:$C$19,MATCH(B10,Items!$A$5:$A$19,0)),"")) | F10: =IF(OR(D10="",E10=""),"",D10*E10) | H10: =IF(OR(A10="",B10="",D10=""),"",IFERROR(INDEX(Items!$D$5:$D$19,MATCH(B10,Items!$A$5:$A$19,0))+SUMIFS(D$4:D9,B$4:B9,B10),"")) | I10: =IF(H10="","",MAX(0,MIN(D10,H10+D10-TotalShipped))) | J10: =IF(H10="","",D10-I10) | K10: =IF(OR(H10="",E10=""),"",I10*E10) | L10: =IF(H10="","",IF(I10>0,TODAY()-A10,"")) | M10: =IF(H10="","",IF(I10<=0,"Shipped",IF(L10<=AGE30,"Fresh",IF(L10<=AGE60,"Watch",IF(L10<=AGE90,"Aging","Old"))))) | N10: =IF(H10="","",J10*A10)
C11: =IF(B11="","",IFERROR(INDEX(Items!$B$5:$B$19,MATCH(B11,Items!$A$5:$A$19,0)),"Unknown code")) | E11: =IF(B11="","",IFERROR(INDEX(Items!$C$5:$C$19,MATCH(B11,Items!$A$5:$A$19,0)),"")) | F11: =IF(OR(D11="",E11=""),"",D11*E11) | H11: =IF(OR(A11="",B11="",D11=""),"",IFERROR(INDEX(Items!$D$5:$D$19,MATCH(B11,Items!$A$5:$A$19,0))+SUMIFS(D$4:D10,B$4:B10,B11),"")) | I11: =IF(H11="","",MAX(0,MIN(D11,H11+D11-TotalShipped))) | J11: =IF(H11="","",D11-I11) | K11: =IF(OR(H11="",E11=""),"",I11*E11) | L11: =IF(H11="","",IF(I11>0,TODAY()-A11,"")) | M11: =IF(H11="","",IF(I11<=0,"Shipped",IF(L11<=AGE30,"Fresh",IF(L11<=AGE60,"Watch",IF(L11<=AGE90,"Aging","Old"))))) | N11: =IF(H11="","",J11*A11)
C12: =IF(B12="","",IFERROR(INDEX(Items!$B$5:$B$19,MATCH(B12,Items!$A$5:$A$19,0)),"Unknown code")) | E12: =IF(B12="","",IFERROR(INDEX(Items!$C$5:$C$19,MATCH(B12,Items!$A$5:$A$19,0)),"")) | F12: =IF(OR(D12="",E12=""),"",D12*E12) | H12: =IF(OR(A12="",B12="",D12=""),"",IFERROR(INDEX(Items!$D$5:$D$19,MATCH(B12,Items!$A$5:$A$19,0))+SUMIFS(D$4:D11,B$4:B11,B12),"")) | I12: =IF(H12="","",MAX(0,MIN(D12,H12+D12-TotalShipped))) | J12: =IF(H12="","",D12-I12) | K12: =IF(OR(H12="",E12=""),"",I12*E12) | L12: =IF(H12="","",IF(I12>0,TODAY()-A12,"")) | M12: =IF(H12="","",IF(I12<=0,"Shipped",IF(L12<=AGE30,"Fresh",IF(L12<=AGE60,"Watch",IF(L12<=AGE90,"Aging","Old"))))) | N12: =IF(H12="","",J12*A12)
C13: =IF(B13="","",IFERROR(INDEX(Items!$B$5:$B$19,MATCH(B13,Items!$A$5:$A$19,0)),"Unknown code")) | E13: =IF(B13="","",IFERROR(INDEX(Items!$C$5:$C$19,MATCH(B13,Items!$A$5:$A$19,0)),"")) | F13: =IF(OR(D13="",E13=""),"",D13*E13) | H13: =IF(OR(A13="",B13="",D13=""),"",IFERROR(INDEX(Items!$D$5:$D$19,MATCH(B13,Items!$A$5:$A$19,0))+SUMIFS(D$4:D12,B$4:B12,B13),"")) | I13: =IF(H13="","",MAX(0,MIN(D13,H13+D13-TotalShipped))) | J13: =IF(H13="","",D13-I13) | K13: =IF(OR(H13="",E13=""),"",I13*E13) | L13: =IF(H13="","",IF(I13>0,TODAY()-A13,"")) | M13: =IF(H13="","",IF(I13<=0,"Shipped",IF(L13<=AGE30,"Fresh",IF(L13<=AGE60,"Watch",IF(L13<=AGE90,"Aging","Old"))))) | N13: =IF(H13="","",J13*A13)
C14: =IF(B14="","",IFERROR(INDEX(Items!$B$5:$B$19,MATCH(B14,Items!$A$5:$A$19,0)),"Unknown code")) | E14: =IF(B14="","",IFERROR(INDEX(Items!$C$5:$C$19,MATCH(B14,Items!$A$5:$A$19,0)),"")) | F14: =IF(OR(D14="",E14=""),"",D14*E14) | H14: =IF(OR(A14="",B14="",D14=""),"",IFERROR(INDEX(Items!$D$5:$D$19,MATCH(B14,Items!$A$5:$A$19,0))+SUMIFS(D$4:D13,B$4:B13,B14),"")) | I14: =IF(H14="","",MAX(0,MIN(D14,H14+D14-TotalShipped))) | J14: =IF(H14="","",D14-I14) | K14: =IF(OR(H14="",E14=""),"",I14*E14) | L14: =IF(H14="","",IF(I14>0,TODAY()-A14,"")) | M14: =IF(H14="","",IF(I14<=0,"Shipped",IF(L14<=AGE30,"Fresh",IF(L14<=AGE60,"Watch",IF(L14<=AGE90,"Aging","Old"))))) | N14: =IF(H14="","",J14*A14)
C15: =IF(B15="","",IFERROR(INDEX(Items!$B$5:$B$19,MATCH(B15,Items!$A$5:$A$19,0)),"Unknown code")) | E15: =IF(B15="","",IFERROR(INDEX(Items!$C$5:$C$19,MATCH(B15,Items!$A$5:$A$19,0)),"")) | F15: =IF(OR(D15="",E15=""),"",D15*E15) | H15: =IF(OR(A15="",B15="",D15=""),"",IFERROR(INDEX(Items!$D$5:$D$19,MATCH(B15,Items!$A$5:$A$19,0))+SUMIFS(D$4:D14,B$4:B14,B15),"")) | I15: =IF(H15="","",MAX(0,MIN(D15,H15+D15-TotalShipped))) | J15: =IF(H15="","",D15-I15) | K15: =IF(OR(H15="",E15=""),"",I15*E15) | L15: =IF(H15="","",IF(I15>0,TODAY()-A15,"")) | M15: =IF(H15="","",IF(I15<=0,"Shipped",IF(L15<=AGE30,"Fresh",IF(L15<=AGE60,"Watch",IF(L15<=AGE90,"Aging","Old"))))) | N15: =IF(H15="","",J15*A15)
C16: =IF(B16="","",IFERROR(INDEX(Items!$B$5:$B$19,MATCH(B16,Items!$A$5:$A$19,0)),"Unknown code")) | E16: =IF(B16="","",IFERROR(INDEX(Items!$C$5:$C$19,MATCH(B16,Items!$A$5:$A$19,0)),"")) | F16: =IF(OR(D16="",E16=""),"",D16*E16) | H16: =IF(OR(A16="",B16="",D16=""),"",IFERROR(INDEX(Items!$D$5:$D$19,MATCH(B16,Items!$A$5:$A$19,0))+SUMIFS(D$4:D15,B$4:B15,B16),"")) | I16: =IF(H16="","",MAX(0,MIN(D16,H16+D16-TotalShipped))) | J16: =IF(H16="","",D16-I16) | K16: =IF(OR(H16="",E16=""),"",I16*E16) | L16: =IF(H16="","",IF(I16>0,TODAY()-A16,"")) | M16: =IF(H16="","",IF(I16<=0,"Shipped",IF(L16<=AGE30,"Fresh",IF(L16<=AGE60,"Watch",IF(L16<=AGE90,"Aging","Old"))))) | N16: =IF(H16="","",J16*A16)
C17: =IF(B17="","",IFERROR(INDEX(Items!$B$5:$B$19,MATCH(B17,Items!$A$5:$A$19,0)),"Unknown code")) | E17: =IF(B17="","",IFERROR(INDEX(Items!$C$5:$C$19,MATCH(B17,Items!$A$5:$A$19,0)),"")) | F17: =IF(OR(D17="",E17=""),"",D17*E17) | H17: =IF(OR(A17="",B17="",D17=""),"",IFERROR(INDEX(Items!$D$5:$D$19,MATCH(B17,Items!$A$5:$A$19,0))+SUMIFS(D$4:D16,B$4:B16,B17),"")) | I17: =IF(H17="","",MAX(0,MIN(D17,H17+D17-TotalShipped))) | J17: =IF(H17="","",D17-I17) | K17: =IF(OR(H17="",E17=""),"",I17*E17) | L17: =IF(H17="","",IF(I17>0,TODAY()-A17,"")) | M17: =IF(H17="","",IF(I17<=0,"Shipped",IF(L17<=AGE30,"Fresh",IF(L17<=AGE60,"Watch",IF(L17<=AGE90,"Aging","Old"))))) | N17: =IF(H17="","",J17*A17)
C18: =IF(B18="","",IFERROR(INDEX(Items!$B$5:$B$19,MATCH(B18,Items!$A$5:$A$19,0)),"Unknown code")) | E18: =IF(B18="","",IFERROR(INDEX(Items!$C$5:$C$19,MATCH(B18,Items!$A$5:$A$19,0)),"")) | F18: =IF(OR(D18="",E18=""),"",D18*E18) | H18: =IF(OR(A18="",B18="",D18=""),"",IFERROR(INDEX(Items!$D$5:$D$19,MATCH(B18,Items!$A$5:$A$19,0))+SUMIFS(D$4:D17,B$4:B17,B18),"")) | I18: =IF(H18="","",MAX(0,MIN(D18,H18+D18-TotalShipped))) | J18: =IF(H18="","",D18-I18) | K18: =IF(OR(H18="",E18=""),"",I18*E18) | L18: =IF(H18="","",IF(I18>0,TODAY()-A18,"")) | M18: =IF(H18="","",IF(I18<=0,"Shipped",IF(L18<=AGE30,"Fresh",IF(L18<=AGE60,"Watch",IF(L18<=AGE90,"Aging","Old"))))) | N18: =IF(H18="","",J18*A18)
C19: =IF(B19="","",IFERROR(INDEX(Items!$B$5:$B$19,MATCH(B19,Items!$A$5:$A$19,0)),"Unknown code")) | E19: =IF(B19="","",IFERROR(INDEX(Items!$C$5:$C$19,MATCH(B19,Items!$A$5:$A$19,0)),"")) | F19: =IF(OR(D19="",E19=""),"",D19*E19) | H19: =IF(OR(A19="",B19="",D19=""),"",IFERROR(INDEX(Items!$D$5:$D$19,MATCH(B19,Items!$A$5:$A$19,0))+SUMIFS(D$4:D18,B$4:B18,B19),"")) | I19: =IF(H19="","",MAX(0,MIN(D19,H19+D19-TotalShipped))) | J19: =IF(H19="","",D19-I19) | K19: =IF(OR(H19="",E19=""),"",I19*E19) | L19: =IF(H19="","",IF(I19>0,TODAY()-A19,"")) | M19: =IF(H19="","",IF(I19<=0,"Shipped",IF(L19<=AGE30,"Fresh",IF(L19<=AGE60,"Watch",IF(L19<=AGE90,"Aging","Old"))))) | N19: =IF(H19="","",J19*A19)
C20: =IF(B20="","",IFERROR(INDEX(Items!$B$5:$B$19,MATCH(B20,Items!$A$5:$A$19,0)),"Unknown code")) | E20: =IF(B20="","",IFERROR(INDEX(Items!$C$5:$C$19,MATCH(B20,Items!$A$5:$A$19,0)),"")) | F20: =IF(OR(D20="",E20=""),"",D20*E20) | H20: =IF(OR(A20="",B20="",D20=""),"",IFERROR(INDEX(Items!$D$5:$D$19,MATCH(B20,Items!$A$5:$A$19,0))+SUMIFS(D$4:D19,B$4:B19,B20),"")) | I20: =IF(H20="","",MAX(0,MIN(D20,H20+D20-TotalShipped))) | J20: =IF(H20="","",D20-I20) | K20: =IF(OR(H20="",E20=""),"",I20*E20) | L20: =IF(H20="","",IF(I20>0,TODAY()-A20,"")) | M20: =IF(H20="","",IF(I20<=0,"Shipped",IF(L20<=AGE30,"Fresh",IF(L20<=AGE60,"Watch",IF(L20<=AGE90,"Aging","Old"))))) | N20: =IF(H20="","",J20*A20)
C21: =IF(B21="","",IFERROR(INDEX(Items!$B$5:$B$19,MATCH(B21,Items!$A$5:$A$19,0)),"Unknown code")) | E21: =IF(B21="","",IFERROR(INDEX(Items!$C$5:$C$19,MATCH(B21,Items!$A$5:$A$19,0)),"")) | F21: =IF(OR(D21="",E21=""),"",D21*E21) | H21: =IF(OR(A21="",B21="",D21=""),"",IFERROR(INDEX(Items!$D$5:$D$19,MATCH(B21,Items!$A$5:$A$19,0))+SUMIFS(D$4:D20,B$4:B20,B21),"")) | I21: =IF(H21="","",MAX(0,MIN(D21,H21+D21-TotalShipped))) | J21: =IF(H21="","",D21-I21) | K21: =IF(OR(H21="",E21=""),"",I21*E21) | L21: =IF(H21="","",IF(I21>0,TODAY()-A21,"")) | M21: =IF(H21="","",IF(I21<=0,"Shipped",IF(L21<=AGE30,"Fresh",IF(L21<=AGE60,"Watch",IF(L21<=AGE90,"Aging","Old"))))) | N21: =IF(H21="","",J21*A21)
C22: =IF(B22="","",IFERROR(INDEX(Items!$B$5:$B$19,MATCH(B22,Items!$A$5:$A$19,0)),"Unknown code")) | E22: =IF(B22="","",IFERROR(INDEX(Items!$C$5:$C$19,MATCH(B22,Items!$A$5:$A$19,0)),"")) | F22: =IF(OR(D22="",E22=""),"",D22*E22) | H22: =IF(OR(A22="",B22="",D22=""),"",IFERROR(INDEX(Items!$D$5:$D$19,MATCH(B22,Items!$A$5:$A$19,0))+SUMIFS(D$4:D21,B$4:B21,B22),"")) | I22: =IF(H22="","",MAX(0,MIN(D22,H22+D22-TotalShipped))) | J22: =IF(H22="","",D22-I22) | K22: =IF(OR(H22="",E22=""),"",I22*E22) | L22: =IF(H22="","",IF(I22>0,TODAY()-A22,"")) | M22: =IF(H22="","",IF(I22<=0,"Shipped",IF(L22<=AGE30,"Fresh",IF(L22<=AGE60,"Watch",IF(L22<=AGE90,"Aging","Old"))))) | N22: =IF(H22="","",J22*A22)
C23: =IF(B23="","",IFERROR(INDEX(Items!$B$5:$B$19,MATCH(B23,Items!$A$5:$A$19,0)),"Unknown code")) | E23: =IF(B23="","",IFERROR(INDEX(Items!$C$5:$C$19,MATCH(B23,Items!$A$5:$A$19,0)),"")) | F23: =IF(OR(D23="",E23=""),"",D23*E23) | H23: =IF(OR(A23="",B23="",D23=""),"",IFERROR(INDEX(Items!$D$5:$D$19,MATCH(B23,Items!$A$5:$A$19,0))+SUMIFS(D$4:D22,B$4:B22,B23),"")) | I23: =IF(H23="","",MAX(0,MIN(D23,H23+D23-TotalShipped))) | J23: =IF(H23="","",D23-I23) | K23: =IF(OR(H23="",E23=""),"",I23*E23) | L23: =IF(H23="","",IF(I23>0,TODAY()-A23,"")) | M23: =IF(H23="","",IF(I23<=0,"Shipped",IF(L23<=AGE30,"Fresh",IF(L23<=AGE60,"Watch",IF(L23<=AGE90,"Aging","Old"))))) | N23: =IF(H23="","",J23*A23)
C24: =IF(B24="","",IFERROR(INDEX(Items!$B$5:$B$19,MATCH(B24,Items!$A$5:$A$19,0)),"Unknown code")) | E24: =IF(B24="","",IFERROR(INDEX(Items!$C$5:$C$19,MATCH(B24,Items!$A$5:$A$19,0)),"")) | F24: =IF(OR(D24="",E24=""),"",D24*E24) | H24: =IF(OR(A24="",B24="",D24=""),"",IFERROR(INDEX(Items!$D$5:$D$19,MATCH(B24,Items!$A$5:$A$19,0))+SUMIFS(D$4:D23,B$4:B23,B24),"")) | I24: =IF(H24="","",MAX(0,MIN(D24,H24+D24-TotalShipped))) | J24: =IF(H24="","",D24-I24) | K24: =IF(OR(H24="",E24=""),"",I24*E24) | L24: =IF(H24="","",IF(I24>0,TODAY()-A24,"")) | M24: =IF(H24="","",IF(I24<=0,"Shipped",IF(L24<=AGE30,"Fresh",IF(L24<=AGE60,"Watch",IF(L24<=AGE90,"Aging","Old"))))) | N24: =IF(H24="","",J24*A24)
C25: =IF(B25="","",IFERROR(INDEX(Items!$B$5:$B$19,MATCH(B25,Items!$A$5:$A$19,0)),"Unknown code")) | E25: =IF(B25="","",IFERROR(INDEX(Items!$C$5:$C$19,MATCH(B25,Items!$A$5:$A$19,0)),"")) | F25: =IF(OR(D25="",E25=""),"",D25*E25) | H25: =IF(OR(A25="",B25="",D25=""),"",IFERROR(INDEX(Items!$D$5:$D$19,MATCH(B25,Items!$A$5:$A$19,0))+SUMIFS(D$4:D24,B$4:B24,B25),"")) | I25: =IF(H25="","",MAX(0,MIN(D25,H25+D25-TotalShipped))) | J25: =IF(H25="","",D25-I25) | K25: =IF(OR(H25="",E25=""),"",I25*E25) | L25: =IF(H25="","",IF(I25>0,TODAY()-A25,"")) | M25: =IF(H25="","",IF(I25<=0,"Shipped",IF(L25<=AGE30,"Fresh",IF(L25<=AGE60,"Watch",IF(L25<=AGE90,"Aging","Old"))))) | N25: =IF(H25="","",J25*A25)
C26: =IF(B26="","",IFERROR(INDEX(Items!$B$5:$B$19,MATCH(B26,Items!$A$5:$A$19,0)),"Unknown code")) | E26: =IF(B26="","",IFERROR(INDEX(Items!$C$5:$C$19,MATCH(B26,Items!$A$5:$A$19,0)),"")) | F26: =IF(OR(D26="",E26=""),"",D26*E26) | H26: =IF(OR(A26="",B26="",D26=""),"",IFERROR(INDEX(Items!$D$5:$D$19,MATCH(B26,Items!$A$5:$A$19,0))+SUMIFS(D$4:D25,B$4:B25,B26),"")) | I26: =IF(H26="","",MAX(0,MIN(D26,H26+D26-TotalShipped))) | J26: =IF(H26="","",D26-I26) | K26: =IF(OR(H26="",E26=""),"",I26*E26) | L26: =IF(H26="","",IF(I26>0,TODAY()-A26,"")) | M26: =IF(H26="","",IF(I26<=0,"Shipped",IF(L26<=AGE30,"Fresh",IF(L26<=AGE60,"Watch",IF(L26<=AGE90,"Aging","Old"))))) | N26: =IF(H26="","",J26*A26)
C27: =IF(B27="","",IFERROR(INDEX(Items!$B$5:$B$19,MATCH(B27,Items!$A$5:$A$19,0)),"Unknown code")) | E27: =IF(B27="","",IFERROR(INDEX(Items!$C$5:$C$19,MATCH(B27,Items!$A$5:$A$19,0)),"")) | F27: =IF(OR(D27="",E27=""),"",D27*E27) | H27: =IF(OR(A27="",B27="",D27=""),"",IFERROR(INDEX(Items!$D$5:$D$19,MATCH(B27,Items!$A$5:$A$19,0))+SUMIFS(D$4:D26,B$4:B26,B27),"")) | I27: =IF(H27="","",MAX(0,MIN(D27,H27+D27-TotalShipped))) | J27: =IF(H27="","",D27-I27) | K27: =IF(OR(H27="",E27=""),"",I27*E27) | L27: =IF(H27="","",IF(I27>0,TODAY()-A27,"")) | M27: =IF(H27="","",IF(I27<=0,"Shipped",IF(L27<=AGE30,"Fresh",IF(L27<=AGE60,"Watch",IF(L27<=AGE90,"Aging","Old"))))) | N27: =IF(H27="","",J27*A27)
C28: =IF(B28="","",IFERROR(INDEX(Items!$B$5:$B$19,MATCH(B28,Items!$A$5:$A$19,0)),"Unknown code")) | E28: =IF(B28="","",IFERROR(INDEX(Items!$C$5:$C$19,MATCH(B28,Items!$A$5:$A$19,0)),"")) | F28: =IF(OR(D28="",E28=""),"",D28*E28) | H28: =IF(OR(A28="",B28="",D28=""),"",IFERROR(INDEX(Items!$D$5:$D$19,MATCH(B28,Items!$A$5:$A$19,0))+SUMIFS(D$4:D27,B$4:B27,B28),"")) | I28: =IF(H28="","",MAX(0,MIN(D28,H28+D28-TotalShipped))) | J28: =IF(H28="","",D28-I28) | K28: =IF(OR(H28="",E28=""),"",I28*E28) | L28: =IF(H28="","",IF(I28>0,TODAY()-A28,"")) | M28: =IF(H28="","",IF(I28<=0,"Shipped",IF(L28<=AGE30,"Fresh",IF(L28<=AGE60,"Watch",IF(L28<=AGE90,"Aging","Old"))))) | N28: =IF(H28="","",J28*A28)
C29: =IF(B29="","",IFERROR(INDEX(Items!$B$5:$B$19,MATCH(B29,Items!$A$5:$A$19,0)),"Unknown code")) | E29: =IF(B29="","",IFERROR(INDEX(Items!$C$5:$C$19,MATCH(B29,Items!$A$5:$A$19,0)),"")) | F29: =IF(OR(D29="",E29=""),"",D29*E29) | H29: =IF(OR(A29="",B29="",D29=""),"",IFERROR(INDEX(Items!$D$5:$D$19,MATCH(B29,Items!$A$5:$A$19,0))+SUMIFS(D$4:D28,B$4:B28,B29),"")) | I29: =IF(H29="","",MAX(0,MIN(D29,H29+D29-TotalShipped))) | J29: =IF(H29="","",D29-I29) | K29: =IF(OR(H29="",E29=""),"",I29*E29) | L29: =IF(H29="","",IF(I29>0,TODAY()-A29,"")) | M29: =IF(H29="","",IF(I29<=0,"Shipped",IF(L29<=AGE30,"Fresh",IF(L29<=AGE60,"Watch",IF(L29<=AGE90,"Aging","Old"))))) | N29: =IF(H29="","",J29*A29)
C30: =IF(B30="","",IFERROR(INDEX(Items!$B$5:$B$19,MATCH(B30,Items!$A$5:$A$19,0)),"Unknown code")) | E30: =IF(B30="","",IFERROR(INDEX(Items!$C$5:$C$19,MATCH(B30,Items!$A$5:$A$19,0)),"")) | F30: =IF(OR(D30="",E30=""),"",D30*E30) | H30: =IF(OR(A30="",B30="",D30=""),"",IFERROR(INDEX(Items!$D$5:$D$19,MATCH(B30,Items!$A$5:$A$19,0))+SUMIFS(D$4:D29,B$4:B29,B30),"")) | I30: =IF(H30="","",MAX(0,MIN(D30,H30+D30-TotalShipped))) | J30: =IF(H30="","",D30-I30) | K30: =IF(OR(H30="",E30=""),"",I30*E30) | L30: =IF(H30="","",IF(I30>0,TODAY()-A30,"")) | M30: =IF(H30="","",IF(I30<=0,"Shipped",IF(L30<=AGE30,"Fresh",IF(L30<=AGE60,"Watch",IF(L30<=AGE90,"Aging","Old"))))) | N30: =IF(H30="","",J30*A30)
C31: =IF(B31="","",IFERROR(INDEX(Items!$B$5:$B$19,MATCH(B31,Items!$A$5:$A$19,0)),"Unknown code")) | E31: =IF(B31="","",IFERROR(INDEX(Items!$C$5:$C$19,MATCH(B31,Items!$A$5:$A$19,0)),"")) | F31: =IF(OR(D31="",E31=""),"",D31*E31) | H31: =IF(OR(A31="",B31="",D31=""),"",IFERROR(INDEX(Items!$D$5:$D$19,MATCH(B31,Items!$A$5:$A$19,0))+SUMIFS(D$4:D30,B$4:B30,B31),"")) | I31: =IF(H31="","",MAX(0,MIN(D31,H31+D31-TotalShipped))) | J31: =IF(H31="","",D31-I31) | K31: =IF(OR(H31="",E31=""),"",I31*E31) | L31: =IF(H31="","",IF(I31>0,TODAY()-A31,"")) | M31: =IF(H31="","",IF(I31<=0,"Shipped",IF(L31<=AGE30,"Fresh",IF(L31<=AGE60,"Watch",IF(L31<=AGE90,"Aging","Old"))))) | N31: =IF(H31="","",J31*A31)
C32: =IF(B32="","",IFERROR(INDEX(Items!$B$5:$B$19,MATCH(B32,Items!$A$5:$A$19,0)),"Unknown code")) | E32: =IF(B32="","",IFERROR(INDEX(Items!$C$5:$C$19,MATCH(B32,Items!$A$5:$A$19,0)),"")) | F32: =IF(OR(D32="",E32=""),"",D32*E32) | H32: =IF(OR(A32="",B32="",D32=""),"",IFERROR(INDEX(Items!$D$5:$D$19,MATCH(B32,Items!$A$5:$A$19,0))+SUMIFS(D$4:D31,B$4:B31,B32),"")) | I32: =IF(H32="","",MAX(0,MIN(D32,H32+D32-TotalShipped))) | J32: =IF(H32="","",D32-I32) | K32: =IF(OR(H32="",E32=""),"",I32*E32) | L32: =IF(H32="","",IF(I32>0,TODAY()-A32,"")) | M32: =IF(H32="","",IF(I32<=0,"Shipped",IF(L32<=AGE30,"Fresh",IF(L32<=AGE60,"Watch",IF(L32<=AGE90,"Aging","Old"))))) | N32: =IF(H32="","",J32*A32)
C33: =IF(B33="","",IFERROR(INDEX(Items!$B$5:$B$19,MATCH(B33,Items!$A$5:$A$19,0)),"Unknown code")) | E33: =IF(B33="","",IFERROR(INDEX(Items!$C$5:$C$19,MATCH(B33,Items!$A$5:$A$19,0)),"")) | F33: =IF(OR(D33="",E33=""),"",D33*E33) | H33: =IF(OR(A33="",B33="",D33=""),"",IFERROR(INDEX(Items!$D$5:$D$19,MATCH(B33,Items!$A$5:$A$19,0))+SUMIFS(D$4:D32,B$4:B32,B33),"")) | I33: =IF(H33="","",MAX(0,MIN(D33,H33+D33-TotalShipped))) | J33: =IF(H33="","",D33-I33) | K33: =IF(OR(H33="",E33=""),"",I33*E33) | L33: =IF(H33="","",IF(I33>0,TODAY()-A33,"")) | M33: =IF(H33="","",IF(I33<=0,"Shipped",IF(L33<=AGE30,"Fresh",IF(L33<=AGE60,"Watch",IF(L33<=AGE90,"Aging","Old"))))) | N33: =IF(H33="","",J33*A33)
C34: =IF(B34="","",IFERROR(INDEX(Items!$B$5:$B$19,MATCH(B34,Items!$A$5:$A$19,0)),"Unknown code")) | E34: =IF(B34="","",IFERROR(INDEX(Items!$C$5:$C$19,MATCH(B34,Items!$A$5:$A$19,0)),"")) | F34: =IF(OR(D34="",E34=""),"",D34*E34) | H34: =IF(OR(A34="",B34="",D34=""),"",IFERROR(INDEX(Items!$D$5:$D$19,MATCH(B34,Items!$A$5:$A$19,0))+SUMIFS(D$4:D33,B$4:B33,B34),"")) | I34: =IF(H34="","",MAX(0,MIN(D34,H34+D34-TotalShipped))) | J34: =IF(H34="","",D34-I34) | K34: =IF(OR(H34="",E34=""),"",I34*E34) | L34: =IF(H34="","",IF(I34>0,TODAY()-A34,"")) | M34: =IF(H34="","",IF(I34<=0,"Shipped",IF(L34<=AGE30,"Fresh",IF(L34<=AGE60,"Watch",IF(L34<=AGE90,"Aging","Old"))))) | N34: =IF(H34="","",J34*A34)
C35: =IF(B35="","",IFERROR(INDEX(Items!$B$5:$B$19,MATCH(B35,Items!$A$5:$A$19,0)),"Unknown code")) | E35: =IF(B35="","",IFERROR(INDEX(Items!$C$5:$C$19,MATCH(B35,Items!$A$5:$A$19,0)),"")) | F35: =IF(OR(D35="",E35=""),"",D35*E35) | H35: =IF(OR(A35="",B35="",D35=""),"",IFERROR(INDEX(Items!$D$5:$D$19,MATCH(B35,Items!$A$5:$A$19,0))+SUMIFS(D$4:D34,B$4:B34,B35),"")) | I35: =IF(H35="","",MAX(0,MIN(D35,H35+D35-TotalShipped))) | J35: =IF(H35="","",D35-I35) | K35: =IF(OR(H35="",E35=""),"",I35*E35) | L35: =IF(H35="","",IF(I35>0,TODAY()-A35,"")) | M35: =IF(H35="","",IF(I35<=0,"Shipped",IF(L35<=AGE30,"Fresh",IF(L35<=AGE60,"Watch",IF(L35<=AGE90,"Aging","Old"))))) | N35: =IF(H35="","",J35*A35)
C36: =IF(B36="","",IFERROR(INDEX(Items!$B$5:$B$19,MATCH(B36,Items!$A$5:$A$19,0)),"Unknown code")) | E36: =IF(B36="","",IFERROR(INDEX(Items!$C$5:$C$19,MATCH(B36,Items!$A$5:$A$19,0)),"")) | F36: =IF(OR(D36="",E36=""),"",D36*E36) | H36: =IF(OR(A36="",B36="",D36=""),"",IFERROR(INDEX(Items!$D$5:$D$19,MATCH(B36,Items!$A$5:$A$19,0))+SUMIFS(D$4:D35,B$4:B35,B36),"")) | I36: =IF(H36="","",MAX(0,MIN(D36,H36+D36-TotalShipped))) | J36: =IF(H36="","",D36-I36) | K36: =IF(OR(H36="",E36=""),"",I36*E36) | L36: =IF(H36="","",IF(I36>0,TODAY()-A36,"")) | M36: =IF(H36="","",IF(I36<=0,"Shipped",IF(L36<=AGE30,"Fresh",IF(L36<=AGE60,"Watch",IF(L36<=AGE90,"Aging","Old"))))) | N36: =IF(H36="","",J36*A36)
C37: =IF(B37="","",IFERROR(INDEX(Items!$B$5:$B$19,MATCH(B37,Items!$A$5:$A$19,0)),"Unknown code")) | E37: =IF(B37="","",IFERROR(INDEX(Items!$C$5:$C$19,MATCH(B37,Items!$A$5:$A$19,0)),"")) | F37: =IF(OR(D37="",E37=""),"",D37*E37) | H37: =IF(OR(A37="",B37="",D37=""),"",IFERROR(INDEX(Items!$D$5:$D$19,MATCH(B37,Items!$A$5:$A$19,0))+SUMIFS(D$4:D36,B$4:B36,B37),"")) | I37: =IF(H37="","",MAX(0,MIN(D37,H37+D37-TotalShipped))) | J37: =IF(H37="","",D37-I37) | K37: =IF(OR(H37="",E37=""),"",I37*E37) | L37: =IF(H37="","",IF(I37>0,TODAY()-A37,"")) | M37: =IF(H37="","",IF(I37<=0,"Shipped",IF(L37<=AGE30,"Fresh",IF(L37<=AGE60,"Watch",IF(L37<=AGE90,"Aging","Old"))))) | N37: =IF(H37="","",J37*A37)
C38: =IF(B38="","",IFERROR(INDEX(Items!$B$5:$B$19,MATCH(B38,Items!$A$5:$A$19,0)),"Unknown code")) | E38: =IF(B38="","",IFERROR(INDEX(Items!$C$5:$C$19,MATCH(B38,Items!$A$5:$A$19,0)),"")) | F38: =IF(OR(D38="",E38=""),"",D38*E38) | H38: =IF(OR(A38="",B38="",D38=""),"",IFERROR(INDEX(Items!$D$5:$D$19,MATCH(B38,Items!$A$5:$A$19,0))+SUMIFS(D$4:D37,B$4:B37,B38),"")) | I38: =IF(H38="","",MAX(0,MIN(D38,H38+D38-TotalShipped))) | J38: =IF(H38="","",D38-I38) | K38: =IF(OR(H38="",E38=""),"",I38*E38) | L38: =IF(H38="","",IF(I38>0,TODAY()-A38,"")) | M38: =IF(H38="","",IF(I38<=0,"Shipped",IF(L38<=AGE30,"Fresh",IF(L38<=AGE60,"Watch",IF(L38<=AGE90,"Aging","Old"))))) | N38: =IF(H38="","",J38*A38)
C39: =IF(B39="","",IFERROR(INDEX(Items!$B$5:$B$19,MATCH(B39,Items!$A$5:$A$19,0)),"Unknown code")) | E39: =IF(B39="","",IFERROR(INDEX(Items!$C$5:$C$19,MATCH(B39,Items!$A$5:$A$19,0)),"")) | F39: =IF(OR(D39="",E39=""),"",D39*E39) | H39: =IF(OR(A39="",B39="",D39=""),"",IFERROR(INDEX(Items!$D$5:$D$19,MATCH(B39,Items!$A$5:$A$19,0))+SUMIFS(D$4:D38,B$4:B38,B39),"")) | I39: =IF(H39="","",MAX(0,MIN(D39,H39+D39-TotalShipped))) | J39: =IF(H39="","",D39-I39) | K39: =IF(OR(H39="",E39=""),"",I39*E39) | L39: =IF(H39="","",IF(I39>0,TODAY()-A39,"")) | M39: =IF(H39="","",IF(I39<=0,"Shipped",IF(L39<=AGE30,"Fresh",IF(L39<=AGE60,"Watch",IF(L39<=AGE90,"Aging","Old"))))) | N39: =IF(H39="","",J39*A39)
C40: =IF(B40="","",IFERROR(INDEX(Items!$B$5:$B$19,MATCH(B40,Items!$A$5:$A$19,0)),"Unknown code")) | E40: =IF(B40="","",IFERROR(INDEX(Items!$C$5:$C$19,MATCH(B40,Items!$A$5:$A$19,0)),"")) | F40: =IF(OR(D40="",E40=""),"",D40*E40) | H40: =IF(OR(A40="",B40="",D40=""),"",IFERROR(INDEX(Items!$D$5:$D$19,MATCH(B40,Items!$A$5:$A$19,0))+SUMIFS(D$4:D39,B$4:B39,B40),"")) | I40: =IF(H40="","",MAX(0,MIN(D40,H40+D40-TotalShipped))) | J40: =IF(H40="","",D40-I40) | K40: =IF(OR(H40="",E40=""),"",I40*E40) | L40: =IF(H40="","",IF(I40>0,TODAY()-A40,"")) | M40: =IF(H40="","",IF(I40<=0,"Shipped",IF(L40<=AGE30,"Fresh",IF(L40<=AGE60,"Watch",IF(L40<=AGE90,"Aging","Old"))))) | N40: =IF(H40="","",J40*A40)
C41: =IF(B41="","",IFERROR(INDEX(Items!$B$5:$B$19,MATCH(B41,Items!$A$5:$A$19,0)),"Unknown code")) | E41: =IF(B41="","",IFERROR(INDEX(Items!$C$5:$C$19,MATCH(B41,Items!$A$5:$A$19,0)),"")) | F41: =IF(OR(D41="",E41=""),"",D41*E41) | H41: =IF(OR(A41="",B41="",D41=""),"",IFERROR(INDEX(Items!$D$5:$D$19,MATCH(B41,Items!$A$5:$A$19,0))+SUMIFS(D$4:D40,B$4:B40,B41),"")) | I41: =IF(H41="","",MAX(0,MIN(D41,H41+D41-TotalShipped))) | J41: =IF(H41="","",D41-I41) | K41: =IF(OR(H41="",E41=""),"",I41*E41) | L41: =IF(H41="","",IF(I41>0,TODAY()-A41,"")) | M41: =IF(H41="","",IF(I41<=0,"Shipped",IF(L41<=AGE30,"Fresh",IF(L41<=AGE60,"Watch",IF(L41<=AGE90,"Aging","Old"))))) | N41: =IF(H41="","",J41*A41)
...

Sheet Shipping
A1: Shipping Log - Finished Products Shipped
A2: Add one row per shipment in the next empty row (keep rows in date order). Each finished product removes one of EVERY component from stock.
A4: Date Shipped | B4: Order / Serial # | C4: Qty of Finished Products Shipped | D4: Notes (optional)
A5: 46354 | B5: 5674

Sheet Settings
A1: Settings
A2: Yellow cells are inputs. Everything else calculates automatically.
A4: Go-live date (date opening inventory was counted) | B4: 46309 | C4: ASSUMPTION: set to the date this system starts. Opening stock is treated as received on this date, so its aging starts at zero here.
A5: Aging: 'Fresh' up to (days) | B5: 60 | C5: Default 30. Stock older than this becomes 'Watch'.
A6: Aging: 'Watch' up to (days) | B6: 120 | C6: Default 60. Stock older than this becomes 'Aging'.
A7: Aging: 'Aging' up to (days) | B7: 300 | C7: Default 90. Stock older than this becomes 'Old'.
A9: Calculated values used by other sheets (do not edit)
A10: Finished products shipped (total) | B10: =SUM(Shipping!$C$5:$C$1004) -> 0 | C10: Each shipped product uses exactly one of every component (given by the company).
A11: Sum of (ship date x qty) over all shipments | B11: =SUMPRODUCT(Shipping!$A$5:$A$1004,Shipping!$C$5:$C$1004) -> 0 | C11: Helper for the average-days-to-ship calculation.
A12: Opening stock still on hand, at cost | B12: =SUMPRODUCT(Items!$I$5:$I$19,Items!$C$5:$C$19) -> 142542 | C12: Opening units not yet shipped x unit cost.
A13: Age of opening stock today (days) | B13: =TODAY()-StartDate -> 1
